<?xml version="1.0" ?>
<!-- =================================================================================== -->
<!-- |    This document was autogenerated by xacro from /home/jviereck_local/dev/nyu_finger/workspace/src/catkin/robots/robot_properties/robot_properties_fingers/xacro/edu/fingeredu.urdf.xacro | -->
<!-- |    EDITING THIS FILE BY HAND IS NOT RECOMMENDED                                 | -->
<!-- =================================================================================== -->
<robot name="coinsPlanar_v1" xmlns:xacro="https://ei.is.tuebingen.mpg.de/xacro">
  <!--
    Frames are defined such that they all align with the base frame when all
    joints are at position zero.

    In zero-configuration the origins of all joints are in one line.

    In zero-configuration the origin of the base link is exactly above the
    finger tip which should make it easy to place the finger in the world.
    -->
  <!--
    Frames are defined such that they all align with the base frame when all
    joints are at position zero.

    In zero-configuration the origins of all joints are in one line.
    -->
  <material name="fingeredu_material">
    <color rgba="0.6 0.6 0.6 1.0"/>
  </material>
  <link name="base_link">
    <visual>
      <origin rpy="0 0 0" xyz="0 0 0"/>
      <geometry>
        <mesh filename="package://example-robot-data/robots/guesss_description/meshes/ellipse.obj" scale="1 1 1"/>
      </geometry>
      <material name="fingeredu_material"/>
    </visual>
    <collision>
      <origin rpy="0 0 0" xyz="0 0 0"/>
      <geometry>
        <mesh filename="package://example-robot-data/robots/guesss_description/meshes/ellipse.obj" scale="1 1 1"/>
      </geometry>
    </collision>
    <inertial>
      <!-- Note: This uses the values from the middle link, assuming
                     that it is similar enough. -->
      <!-- CoM is only estimated based -->
      <origin rpy="0 0 0" xyz="0 0 0"/>
      <mass value="6.47e-3"/>
      <inertia ixx="7.06e-7" ixy="0." ixz="0." iyy="1.36e-6" iyz="0." izz="7.06e-7"/>
    </inertial>
  </link>
  <link name="wing2">
    <visual>
      <origin rpy="0 0 0" xyz="0 0 0"/>
      <geometry>
        <mesh filename="package://example-robot-data/robots/guesss_description/meshes/ellipse.obj" scale="1 1 1"/>
      </geometry>
      <material name="fingeredu_material"/>
    </visual>
    <collision>
      <origin rpy="0 0 0" xyz="0 0 0"/>
      <geometry>
        <mesh filename="package://example-robot-data/robots/guesss_description/meshes/ellipse.obj" scale="1 1 1"/>
      </geometry>
    </collision>
    <inertial>
      <!-- Note: This uses the values from the middle link, assuming
                     that it is similar enough. -->
      <!-- CoM is only estimated based -->
      <origin rpy="0 0 0" xyz="0 0 0"/>
      <mass value="1.294e-3"/>
      <inertia ixx="1.412e-7" ixy="0." ixz="0." iyy="2.72e-7" iyz="0." izz="1.412e-7"/>
    </inertial>
  </link>
  <joint name="wing_joint" type="revolute">
    <parent link="base_link"/>
    <child link="wing2"/>
    <!-- <limit effort="1000" lower="-1.5" upper="1.5" velocity="1000"/> -->
    <limit effort="1000" lower="-3.14159265359" upper="3.14159265359" velocity="1000"/>
    <axis xyz="1 0 0"/>
    <origin rpy="0 0 0" xyz="0 0 0"/>
  </joint>
</robot>