<?xml version="1.0" ?>
<!-- =================================================================================== -->
<!-- |    This document was autogenerated by xacro from /home/jviereck_local/dev/nyu_finger/workspace/src/catkin/robots/robot_properties/robot_properties_fingers/xacro/edu/fingeredu.urdf.xacro | -->
<!-- |    EDITING THIS FILE BY HAND IS NOT RECOMMENDED                                 | -->
<!-- =================================================================================== -->
<robot name="grasp_v7x10_bt" xmlns:xacro="https://ei.is.tuebingen.mpg.de/xacro">
  <material name="fingeredu_material">
    <color rgba="0.6 0.6 0.6 1.0"/>
  </material>
  <link name="base_link">
    <inertial>
      <origin rpy="0 0 0" xyz="0 0 0"/>
      <mass value="0"/>
      <inertia ixx="0." ixy="0." ixz="0." iyy="0." iyz="0." izz="0."/>
    </inertial>
  </link>
  <link name="col">
    <visual>
      <origin rpy="0 0 0" xyz="0 -0.06 0"/>
      <geometry>
        <mesh filename="package://example-robot-data/robots/guesss_description/meshes/cylinder_v0x10.obj" scale="1 1 1"/>
      </geometry>
      <material name="fingeredu_material"/>
    </visual>
    <collision>
      <origin rpy="0 0 0" xyz="0 -0.06 0"/>
      <geometry>
        <mesh filename="package://example-robot-data/robots/guesss_description/meshes/cylinder_v0x10.obj" scale="1 1 1"/>
      </geometry>
    </collision>
    <inertial>
      <origin rpy="0 0 0" xyz="0 -0.06 0"/>
      <mass value="2.46992614e1"/>
      <inertia ixx="7.12476394" ixy="0." ixz="0." iyy="7.12441251" iyz="0." izz="8.77925345e-02"/>
    </inertial>
  </link>
  <link name="gripper1">
    <visual>
      <origin rpy="-1.570796 0 0" xyz="0 0 0"/>
      <geometry>
        <mesh filename="package://example-robot-data/robots/guesss_description/meshes/finger_v0x40.obj" scale="1 1 1"/>
      </geometry>
      <material name="fingeredu_material"/>
    </visual>
    <collision>
      <origin rpy="-1.570796 0 0" xyz="0 0 0"/>
      <geometry>
        <mesh filename="package://example-robot-data/robots/guesss_description/meshes/finger_v0x40.obj" scale="1 1 1"/>
      </geometry>
    </collision>
    <inertial>
      <origin rpy="-1.570796 0 0" xyz="0 0 0"/>
      <mass value="6.26903772e2"/>
      <inertia ixx="5.94189810e2" ixy="0." ixz="0." iyy="6.00707252e2" iyz="-9.19601414e1" izz="9.88141168e1"/>
    </inertial>
  </link>
  <link name="gripper2">
    <visual>
      <origin rpy="-1.570796 0 0" xyz="0 0 0"/>
      <geometry>
        <mesh filename="package://example-robot-data/robots/guesss_description/meshes/finger_v0x40_p.obj" scale="1 1 1"/>
      </geometry>
      <material name="fingeredu_material"/>
    </visual>
    <collision>
      <origin rpy="-1.570796 0 0" xyz="0 0 0"/>
      <geometry>
        <mesh filename="package://example-robot-data/robots/guesss_description/meshes/finger_v0x40_p.obj" scale="1 1 1"/>
      </geometry>
    </collision>
    <inertial>
      <origin rpy="-1.570796 0 0" xyz="0 0 0"/>
      <mass value="6.26903772e2"/>
      <inertia ixx="5.94189810e2" ixy="0." ixz="0." iyy="6.00707252e2" iyz="9.19601414e1" izz="9.88141168e1"/>
    </inertial>
  </link>
  <link name="temp_y">
    <inertial>
      <origin rpy="0 0 0" xyz="0 0 0"/>
      <mass value="6.47e-10"/>
      <inertia ixx="0." ixy="0." ixz="0." iyy="0." iyz="0." izz="0."/>
    </inertial>
  </link>
  <link name="temp_z">
    <inertial>
      <origin rpy="0 0 0" xyz="0 0 0"/>
      <mass value="6.47e-10"/>
      <inertia ixx="0." ixy="0." ixz="0." iyy="0." iyz="0." izz="0."/>
    </inertial>
  </link>
  <link name="coin">
    <visual>
      <origin rpy="0 0 0" xyz="0 0 0"/>
      <geometry>
        <mesh filename="package://example-robot-data/robots/guesss_description/meshes/ellipseV4x10.obj" scale="1 1 1"/>
      </geometry>
      <material name="fingeredu_material"/>
    </visual>
    <collision>
      <origin rpy="0 0 0" xyz="0 0 0"/>
      <geometry>
        <mesh filename="package://example-robot-data/robots/guesss_description/meshes/ellipseV4x10.obj" scale="1 1 1"/>
      </geometry>
    </collision>
    <inertial>
      <origin rpy="0 0 0" xyz="0 0 0"/>
      <mass value="1.07760802e1"/>
      <inertia ixx="1.30175886e-1" ixy="0." ixz="0." iyy="2.35957441e-1" iyz="0." izz="1.30167427e-1"/>
    </inertial>
  </link>
  <joint name="col_joint" type="prismatic">
    <parent link="base_link"/>
    <child link="col"/>
    <limit effort="1000" lower="-30.14159265359" upper="30.14159265359" velocity="1000"/>
    <axis xyz="0 1 0"/>
    <origin rpy="0 0 0" xyz="0 0 0"/>
  </joint>
  <joint name="finger_joint1" type="prismatic">
    <parent link="col"/>
    <child link="gripper1"/>
    <limit effort="1000" lower="-30.14159265359" upper="30.14159265359" velocity="1000"/>
    <axis xyz="0 0 1"/>
    <origin rpy="0 0 0" xyz="0 0 0"/>
  </joint>
  <joint name="finger_joint2" type="prismatic">
    <parent link="col"/>
    <child link="gripper2"/>
    <limit effort="1000" lower="-30.14159265359" upper="30.14159265359" velocity="1000"/>
    <axis xyz="0 0 1"/>
    <origin rpy="0 0 0" xyz="0 0 0"/>
  </joint>
  <joint name="coin_joint_y" type="prismatic">
    <parent link="base_link"/>
    <child link="temp_y"/>
    <limit effort="1000" lower="-30.14159265359" upper="30.14159265359" velocity="1000"/>
    <axis xyz="0 1 0"/>
    <origin rpy="0 0 0" xyz="0 0 0"/>
  </joint>
  <joint name="coin_joint_z" type="prismatic">
    <parent link="temp_y"/>
    <child link="temp_z"/>
    <limit effort="1000" lower="-30.14159265359" upper="30.14159265359" velocity="1000"/>
    <axis xyz="0 0 1"/>
    <origin rpy="0 0 0" xyz="0 0 0"/>
  </joint>
  <joint name="coin_joint_x" type="revolute">
    <parent link="temp_z"/>
    <child link="coin"/>
    <limit effort="10000" lower="-3.14159265359" upper="3.14159265359" velocity="10000"/>
    <axis xyz="1 0 0"/>
    <origin rpy="0 0 0" xyz="0 0 0"/>
  </joint>
</robot>