<?xml version="1.0" ?>
<!-- =================================================================================== -->
<!-- |    This document was autogenerated by xacro from /home/jviereck_local/dev/nyu_finger/workspace/src/catkin/robots/robot_properties/robot_properties_fingers/xacro/edu/fingeredu.urdf.xacro | -->
<!-- |    EDITING THIS FILE BY HAND IS NOT RECOMMENDED                                 | -->
<!-- =================================================================================== -->
<robot name="leaf_v1x10" xmlns:xacro="https://ei.is.tuebingen.mpg.de/xacro">
  <material name="fingeredu_material">
    <color rgba="0.6 0.6 0.6 1.0"/>
  </material>
  <link name="base_link">
    <visual>
      <origin rpy="0 0 0" xyz="0 0 0"/>
      <geometry>
        <mesh filename="package://example-robot-data/robots/guesss_description/meshes/spherex30.obj" scale="1 1 1"/>
      </geometry>
      <material name="fingeredu_material"/>
    </visual>
    <collision>
      <origin rpy="0 0 0" xyz="0 0 0"/>
      <geometry>
        <mesh filename="package://example-robot-data/robots/guesss_description/meshes/spherex30.obj" scale="1 1 1"/>
      </geometry>
    </collision>
    <inertial>
      <origin rpy="0 0 0" xyz="0 0 0"/>
      <mass value="1.1637e3"/>
      <inertia ixx="2.79e2" ixy="0." ixz="0." iyy="2.79e2" iyz="0." izz="2.79e2"/>
    </inertial>
  </link>
  <link name="small_fish">
    <visual>
      <origin rpy="0 0 0" xyz="0 0 0"/>
      <geometry>
        <mesh filename="package://example-robot-data/robots/guesss_description/meshes/ellipse_10.obj" scale="1 1 1"/>
      </geometry>
      <material name="fingeredu_material"/>
    </visual>
    <collision>
      <origin rpy="0 0 0" xyz="0 0 0"/>
      <geometry>
        <mesh filename="package://example-robot-data/robots/guesss_description/meshes/ellipse_10.obj" scale="1 1 1"/>
      </geometry>
    </collision>
    <inertial>
      <origin rpy="0 0 0" xyz="0 0 0"/>
      <mass value="6.47"/>
      <inertia ixx="7.06e-2" ixy="0." ixz="0." iyy="1.36e-1" iyz="0." izz="7.06e-2"/>
    </inertial>
  </link>
  <link name="floor">
    <visual>
      <origin rpy="0 0 0" xyz="0 0 0"/>
      <geometry>
        <mesh filename="package://example-robot-data/robots/guesss_description/meshes/floor_v0x10.obj" scale="1 1 1"/>
      </geometry>
      <material name="fingeredu_material"/>
    </visual>
    <collision>
      <origin rpy="0 0 0" xyz="0 0 0"/>
      <geometry>
        <mesh filename="package://example-robot-data/robots/guesss_description/meshes/floor_v0x10.obj" scale="1 1 1"/>
      </geometry>
    </collision>
    <inertial>
      <origin rpy="0 0 0" xyz="0 0 0"/>
      <mass value="1"/>
      <inertia ixx="5" ixy="0." ixz="0." iyy="5" iyz="0." izz="5"/>
    </inertial>
  </link>
  <joint name="joint1" type="revolute">
    <parent link="base_link"/>
    <child link="small_fish"/>
    <!-- <limit effort="1000" lower="-1.5" upper="1.5" velocity="1000"/> -->
    <limit effort="1000" lower="-3.14159265359" upper="3.14159265359" velocity="1000"/>
    <axis xyz="1 0 0"/>
    <origin rpy="0 0 0" xyz="0 0 0"/>
  </joint>
  <joint name="joint2" type="revolute">
    <parent link="small_fish"/>
    <child link="floor"/>
    <!-- <limit effort="1000" lower="-1.5" upper="1.5" velocity="1000"/> -->
    <limit effort="1000" lower="-3.14159265359" upper="3.14159265359" velocity="1000"/>
    <axis xyz="1 0 0"/>
    <origin rpy="0 0 0" xyz="0 0 0"/>
  </joint>
</robot>