<?xml version="1.0" ?>
<!-- =================================================================================== -->
<!-- |    This document was autogenerated by xacro from /home/jviereck_local/dev/nyu_finger/workspace/src/catkin/robots/robot_properties/robot_properties_fingers/xacro/edu/fingeredu.urdf.xacro | -->
<!-- |    EDITING THIS FILE BY HAND IS NOT RECOMMENDED                                 | -->
<!-- =================================================================================== -->
<robot name="leaf_v1x10_bt" xmlns:xacro="https://ei.is.tuebingen.mpg.de/xacro">
  <material name="fingeredu_material">
    <color rgba="0.6 0.6 0.6 1.0"/>
  </material>
  <link name="base_link">
    <inertial>
      <origin rpy="0 0 0" xyz="0 0 0"/>
      <mass value="0"/>
      <inertia ixx="0." ixy="0." ixz="0." iyy="0." iyz="0." izz="0."/>
    </inertial>
  </link>
  <link name="sphere">
    <visual>
      <origin rpy="0 0 0" xyz="0 0 0"/>
      <geometry>
        <mesh filename="package://example-robot-data/robots/guesss_description/meshes/spherex30.obj" scale="1 1 1"/>
      </geometry>
      <material name="fingeredu_material"/>
    </visual>
    <collision>
      <origin rpy="0 0 0" xyz="0 0 0"/>
      <geometry>
        <mesh filename="package://example-robot-data/robots/guesss_description/meshes/spherex30.obj" scale="1 1 1"/>
      </geometry>
    </collision>
    <inertial>
      <origin rpy="0 0 0" xyz="0 0 0"/>
      <mass value="1.1637e3"/>
      <inertia ixx="2.79e2" ixy="0." ixz="0." iyy="2.79e2" iyz="0." izz="2.79e2"/>
    </inertial>
  </link>
  <link name="temp_y">
    <inertial>
      <origin rpy="0 0 0" xyz="0 0 0"/>
      <mass value="6.47e-10"/>
      <inertia ixx="0." ixy="0." ixz="0." iyy="0." iyz="0." izz="0."/>
    </inertial>
  </link>
  <link name="temp_z">
    <inertial>
      <origin rpy="0 0 0" xyz="0 0 0"/>
      <mass value="6.47e-10"/>
      <inertia ixx="0." ixy="0." ixz="0." iyy="0." iyz="0." izz="0."/>
    </inertial>
  </link>
  <link name="coin">
    <visual>
      <origin rpy="0 0 0" xyz="0 0 0"/>
      <geometry>
        <mesh filename="package://example-robot-data/robots/guesss_description/meshes/ellipse_10.obj" scale="1 1 1"/>
      </geometry>
      <material name="fingeredu_material"/>
    </visual>
    <collision>
      <origin rpy="0 0 0" xyz="0 0 0"/>
      <geometry>
        <mesh filename="package://example-robot-data/robots/guesss_description/meshes/ellipse_10.obj" scale="1 1 1"/>
      </geometry>
    </collision>
    <inertial>
      <origin rpy="0 0 0" xyz="0 0 0"/>
      <mass value="6.47"/>
      <inertia ixx="7.06e-2" ixy="0." ixz="0." iyy="1.36e-1" iyz="0." izz="7.06e-2"/>
    </inertial>
  </link>
  <link name="floor">
    <visual>
      <origin rpy="0 0 0" xyz="0 0 0"/>
      <geometry>
        <mesh filename="package://example-robot-data/robots/guesss_description/meshes/floor_v0x10.obj" scale="1 1 1"/>
      </geometry>
      <material name="fingeredu_material"/>
    </visual>
    <collision>
      <origin rpy="0 0 0" xyz="0 0 0"/>
      <geometry>
        <mesh filename="package://example-robot-data/robots/guesss_description/meshes/floor_v0x10.obj" scale="1 1 1"/>
      </geometry>
    </collision>
    <inertial>
      <origin rpy="0 0 0" xyz="0 0 0"/>
      <mass value="0"/>
      <inertia ixx="0" ixy="0." ixz="0." iyy="0" iyz="0." izz="0"/>
    </inertial>
  </link>
  <joint name="base_shpere" type="prismatic">
    <parent link="base_link"/>
    <child link="sphere"/>
    <limit effort="1000" lower="-30.14159265359" upper="30.14159265359" velocity="1000"/>
    <axis xyz="0 0 1"/>
    <origin rpy="0 0 0" xyz="0 0 0"/>
  </joint>
  <joint name="coin_joint_y" type="prismatic">
    <parent link="base_link"/>
    <child link="temp_y"/>
    <limit effort="1000" lower="-30.14159265359" upper="30.14159265359" velocity="1000"/>
    <axis xyz="0 1 0"/>
    <origin rpy="0 0 0" xyz="0 0 0"/>
  </joint>
  <joint name="coin_joint_z" type="prismatic">
    <parent link="temp_y"/>
    <child link="temp_z"/>
    <limit effort="1000" lower="-30.14159265359" upper="30.14159265359" velocity="1000"/>
    <axis xyz="0 0 1"/>
    <origin rpy="0 0 0" xyz="0 0 0"/>
  </joint>
  <joint name="coin_joint_x" type="revolute">
    <parent link="temp_z"/>
    <child link="coin"/>
    <limit effort="10000" lower="-3.14159265359" upper="3.14159265359" velocity="10000"/>
    <axis xyz="1 0 0"/>
    <origin rpy="0 0 0" xyz="0 0 0"/>
  </joint>
  <joint name="floor_joint" type="prismatic">
    <parent link="base_link"/>
    <child link="floor"/>
    <limit effort="1000" lower="-30.14159265359" upper="30.14159265359" velocity="1000"/>
    <axis xyz="0 0 1"/>
    <origin rpy="0 0 0" xyz="0 0 0"/>
  </joint>
</robot>